Workbook

Sheet Problems
A1: Problem # | B1: Difficulty | C1: Company | D1: Title | E1: Description | F1: Status | G1: Python | H1: JavaScript | I1: TypeScript | J1: Rust | K1: C++ | L1: C | M1: Java | N1: Bash | O1: # Languages
A2: 2 | B2: Hard | C2: Uber | D2: Given an array of integers, return a new array such that each element at index i of the new array is... | E2: Given an array of integers, return a new array such that each element at index i of the new array is the product of all the numbers in the original array except the one at i. For example, if our input was [1, 2, 3, 4, 5], the expected output would be [120, 60, 40, 30, 24]. If our input was [3, 2, 1], the expected output would be [2, 3, 6]. Follow-up: what if you can't use division? | F2: Not Started | O2: =COUNTA(G2:N2) -> 0
A3: 3 | B3: Medium | C3: Google | D3: Given the root to a binary tree, implement serialize(root), which serializes the tree into a string,... | E3: Given the root to a binary tree, implement serialize(root), which serializes the tree into a string, and deserialize(s), which deserializes the string back into the tree. For example, given the following Node class class Node: def __init__(self, val, left=None, right=None): self.val = val self.left = left self.right = right The following test should pass: node = Node('root', Node('left', Node('left.left')), Node('right')) assert deserialize(serialize(node)).left.left.val == 'left.left' | F3: Not Started | O3: =COUNTA(G3:N3) -> 0
A4: 4 | B4: Hard | C4: Stripe | D4: Given an array of integers, find the first missing positive integer in linear time and constant spac... | E4: Given an array of integers, find the first missing positive integer in linear time and constant space. In other words, find the lowest positive integer that does not exist in the array. The array can contain duplicates and negative numbers as well. For example, the input [3, 4, -1, 1] should give 2. The input [1, 2, 0] should give 3. You can modify the input array in-place. | F4: Not Started | O4: =COUNTA(G4:N4) -> 0
A5: 5 | B5: Medium | C5: Jane Street | D5: cons(a, b) constructs a pair, and car(pair) and cdr(pair) returns the first and last element of that... | E5: cons(a, b) constructs a pair, and car(pair) and cdr(pair) returns the first and last element of that pair. For example, car(cons(3, 4)) returns 3, and cdr(cons(3, 4)) returns 4. Given this implementation of cons: def cons(a, b): def pair(f): return f(a, b) return pair Implement car and cdr. | F5: Not Started | O5: =COUNTA(G5:N5) -> 0
A6: 6 | B6: Hard | C6: Google | D6: An XOR linked list is a more memory efficient doubly linked list. | E6: An XOR linked list is a more memory efficient doubly linked list. Instead of each node holding next and prev fields, it holds a field named both, which is an XOR of the next node and the previous node. Implement an XOR linked list; it has an add(element) which adds the element to the end, and a get(index) which returns the node at index. If using a language that has no pointers (such as Python), you can assume you have access to get_pointer anddereference_pointer functions that converts between nodes and memory addresses. | F6: Not Started | O6: =COUNTA(G6:N6) -> 0
A7: 7 | B7: Medium | C7: Facebook | D7: Given the mapping a = 1, b = 2, . | E7: Given the mapping a = 1, b = 2, ... z = 26, and an encoded message, count the number of ways it can be decoded. For example, the message '111' would give 3, since it could be decoded as 'aaa', 'ka', and 'ak'. You can assume that the messages are decodable. For example, '001' is not allowed. | F7: Not Started | O7: =COUNTA(G7:N7) -> 0
A8: 8 | B8: Easy | C8: Google | D8: A unival tree (which stands for "universal value") is a tree where all nodes under it have the same ... | E8: A unival tree (which stands for "universal value") is a tree where all nodes under it have the same value. Given the root to a binary tree, count the number of unival subtrees. For example, the following tree has 5 unival subtrees: 0 / \ 1 0 / \ 1 0 / \ 1 1 | F8: Solved | J8: 45663 | M8: 46028 | O8: =COUNTA(G8:N8) -> 2
A9: 9 | B9: Hard | C9: Airbnb | D9: Given a list of integers, write a function that returns the largest sum of non-adjacent numbers. | E9: Given a list of integers, write a function that returns the largest sum of non-adjacent numbers. Numbers can be 0 or negative. For example, [2, 4, 6, 2, 5] should return 13, since we pick 2, 6, and 5. [5, 1, 1, 5] should return 10, since we pick 5 and 5. Follow-up: Can you do this in O(N) time and constant space? | F9: Not Started | O9: =COUNTA(G9:N9) -> 0
A10: 10 | B10: Medium | C10: Apple | D10: Implement a job scheduler which takes in a function f and an integer n, and calls f after n millisec... | E10: Implement a job scheduler which takes in a function f and an integer n, and calls f after n milliseconds. | F10: Not Started | O10: =COUNTA(G10:N10) -> 0
A11: 11 | B11: Medium | C11: Twitter | D11: Implement an autocomplete system. | E11: Implement an autocomplete system. That is, given a query string s and a set of all possible query strings, return all strings in the set that have s as a prefix. For example, given the query string de and the set of strings [dog, deer, deal], return [deer, deal]. Hint: Try preprocessing the dictionary into a more efficient data structure to speed up queries. | F11: Not Started | O11: =COUNTA(G11:N11) -> 0
A12: 12 | B12: Hard | C12: Amazon | D12: There exists a staircase with N steps, and you can climb up either 1 or 2 steps at a time. | E12: There exists a staircase with N steps, and you can climb up either 1 or 2 steps at a time. Given N, write a function that returns the number of unique ways you can climb the staircase. The order of the steps matters. For example, if N is 4, then there are 5 unique ways: * 1, 1, 1, 1 * 2, 1, 1 * 1, 2, 1 * 1, 1, 2 * 2, 2 What if, instead of being able to climb 1 or 2 steps at a time, you could climb any number from a set of positive integers X? For example, if X = {1, 3, 5}, you could climb 1, 3, or 5 steps at a time. | F12: Not Started | O12: =COUNTA(G12:N12) -> 0
A13: 13 | B13: Hard | C13: Amazon | D13: Given an integer k and a string s, find the length of the longest substring that contains at most k ... | E13: Given an integer k and a string s, find the length of the longest substring that contains at most k distinct characters. For example, given s = "abcba" and k = 2, the longest substring with k distinct characters is "bcb". | F13: Not Started | O13: =COUNTA(G13:N13) -> 0
A14: 14 | B14: Medium | C14: Google | D14: The area of a circle is defined as πr^2. | E14: The area of a circle is defined as πr^2. Estimate π to 3 decimal places using a Monte Carlo method. Hint: The basic equation of a circle is x2 + y2 = r2. | F14: Not Started | O14: =COUNTA(G14:N14) -> 0
A15: 15 | B15: Medium | C15: Facebook | D15: Given a stream of elements too large to store in memory, pick a random element from the stream with ... | E15: Given a stream of elements too large to store in memory, pick a random element from the stream with uniform probability. | F15: Not Started | O15: =COUNTA(G15:N15) -> 0
A16: 16 | B16: Easy | C16: Twitter | D16: You run an e-commerce website and want to record the last N order ids in a log. | E16: You run an e-commerce website and want to record the last N order ids in a log. Implement a data structure to accomplish this, with the following API: * record(order_id): adds the order_id to the log * get_last(i): gets the ith last element from the log. i is guaranteed to be smaller than or equal to N. You should be as efficient with time and space as possible. | F16: Not Started | O16: =COUNTA(G16:N16) -> 0
A17: 17 | B17: Hard | C17: Google | D17: Suppose we represent our file system by a string in the following manner: The string "dir\n\tsubdir1... | E17: Suppose we represent our file system by a string in the following manner: The string "dir\n\tsubdir1\n\tsubdir2\n\t\tfile.ext" represents: dir subdir1 subdir2 file.ext The directory dir contains an empty sub-directory subdir1 and a sub-directory subdir2 containing a file file.ext. The string "dir\n\tsubdir1\n\t\tfile1.ext\n\t\tsubsubdir1\n\tsubdir2\n\t\tsubsubdir2\n\t\t\tfile2.ext" represents: dir subdir1 file1.ext subsubdir1 subdir2 subsubdir2 file2.ext The directory dir contains two sub-directories subdir1 and subdir2. subdir1 contains a file file1.extand an empty second-level sub-directory subsubdir1. subdir2 contains a second-level sub-directorysubsubdir2 containing a file file2.ext. We are interested in finding the longest (number of characters) absolute path to a file within our file system. For example, in the second example above, the longest absolute path is "dir/subdir2/subsubdir2/file2.ext", and its length is 32 (not including the double quotes). Given a string representing | F17: Not Started | O17: =COUNTA(G17:N17) -> 0
A18: 18 | B18: Hard | C18: Google | D18: Given an array of integers and a number k, where 1 <= k <= length of the array, compute the maximum ... | E18: Given an array of integers and a number k, where 1 <= k <= length of the array, compute the maximum values of each subarray of length k. For example, given array = [10, 5, 2, 7, 8, 7] and k = 3, we should get: [10, 7, 8, 8], since: * 10 = max(10, 5, 2) * 7 = max(5, 2, 7) * 8 = max(2, 7, 8) * 8 = max(7, 8, 7) Do this in O(n) time and O(k) space. You can modify the input array in-place and you do not need to store the results. You can simply print them out as you compute them. | F18: Not Started | O18: =COUNTA(G18:N18) -> 0
A19: 19 | B19: Medium | C19: Facebook | D19: A builder is looking to build a row of N houses that can be of K different colors. | E19: A builder is looking to build a row of N houses that can be of K different colors. He has a goal of minimizing cost while ensuring that no two neighboring houses are of the same color. Given an N by K matrix where the nth row and kth column represents the cost to build the nthhouse with kth color, return the minimum cost which achieves this goal. | F19: Not Started | O19: =COUNTA(G19:N19) -> 0
A20: 20 | B20: Easy | C20: Google | D20: Given two singly linked lists that intersect at some point, find the intersecting node. | E20: Given two singly linked lists that intersect at some point, find the intersecting node. The lists are non-cyclical. For example, given A = 3 -> 7 -> 8 -> 10 and B = 99 -> 1 -> 8 -> 10, return the node with value 8. In this example, assume nodes with the same value are the exact same node objects. Do this in O(M + N) time (where M and N are the lengths of the lists) and constant space. | F20: Not Started | O20: =COUNTA(G20:N20) -> 0
... A26: 26 | B26: Medium | C26: Google | D26: Given a singly linked list and an integer k, remove the kth last element from the list. | E26: Given a singly linked list and an integer k, remove the kth last element from the list. k is guaranteed to be smaller than the length of the list. The list is very long, so making more than one pass is prohibitively expensive. Do this in constant space and in one pass. | F26: Not Started | O26: =COUNTA(G26:N26) -> 0
A27: 27 | B27: Easy | C27: Facebook | D27: Given a string of round, curly, and square open and closing brackets, return whether the brackets ar... | E27: Given a string of round, curly, and square open and closing brackets, return whether the brackets are balanced (well-formed). For example, given the string "([])[]({})", you should return true. Given the string "([)]" or "((()", you should return false. | F27: Solved | G27: 46026 | H27: 46028 | J27: 46023 | O27: =COUNTA(G27:N27) -> 3
A28: 28 | B28: Medium | C28: Palantir | D28: Write an algorithm to justify text. | E28: Write an algorithm to justify text. Given a sequence of words and an integer line length k, return a list of strings which represents each line, fully justified. More specifically, you should have as many words as possible in each line. There should be at least one space between each word. Pad extra spaces when necessary so that each line has exactly length k. Spaces should be distributed as equally as possible, with the extra spaces, if any, distributed starting from the left. If you can only fit one word on a line, then you should pad the right-hand side with spaces. Each word is guaranteed not to be longer than k. For example, given the list of words ["the", "quick", "brown", "fox", "jumps", "over", "the", "lazy", "dog"] and k = 16, you should return the following: ["the quick brown", # 1 extra space on the left "fox jumps over", # 2 extra spaces distributed evenly "the lazy dog"] # 4 extra spaces distributed evenly | F28: Not Started | O28: =COUNTA(G28:N28) -> 0
A29: 29 | B29: Easy | C29: Amazon | D29: Run-length encoding is a fast and simple method of encoding strings. | E29: Run-length encoding is a fast and simple method of encoding strings. The basic idea is to represent repeated successive characters as a single count and character. For example, the string "AAAABBBCCDAA" would be encoded as "4A3B2C1D2A". Implement run-length encoding and decoding. You can assume the string to be encoded have no digits and consists solely of alphabetic characters. You can assume the string to be decoded is valid. | F29: Solved | J29: 46030 | O29: =COUNTA(G29:N29) -> 1
A30: 30 | B30: Medium | C30: Facebook | D30: You are given an array of non-negative integers that represents a two-dimensional elevation map wher... | E30: You are given an array of non-negative integers that represents a two-dimensional elevation map where each element is unit-width wall and the integer is the height. Suppose it will rain and all spots between two walls get filled up. Compute how many units of water remain trapped on the map in O(N) time and O(1) space. For example, given the input [2, 1, 2], we can hold 1 unit of water in the middle. Given the input [3, 0, 1, 3, 0, 5], we can hold 3 units in the first index, 2 in the second, and 3 in the fourth index (we cannot hold 5 since it would run off to the left), so we can trap 8 units of water. | F30: Not Started | O30: =COUNTA(G30:N30) -> 0
A31: 31 | B31: Easy | C31: Google | D31: The edit distance between two strings refers to the minimum number of character insertions, deletion... | E31: The edit distance between two strings refers to the minimum number of character insertions, deletions, and substitutions required to change one string to the other. For example, the edit distance between “kitten” and “sitting” is three: substitute the “k” for “s”, substitute the “e” for “i”, and append a “g”. Given two strings, compute the edit distance between them. | F31: Not Started | O31: =COUNTA(G31:N31) -> 0
A32: 32 | B32: Hard | C32: Jane Street | D32: Suppose you are given a table of currency exchange rates, represented as a 2D array. | E32: Suppose you are given a table of currency exchange rates, represented as a 2D array. Determine whether there is a possible arbitrage: that is, whether there is some sequence of trades you can make, starting with some amount A of any currency, so that you can end up with some amount greater than A of that currency. There are no transaction costs and you can trade fractional quantities. | F32: Not Started | O32: =COUNTA(G32:N32) -> 0
A33: 33 | B33: Easy | C33: Microsoft | D33: Compute the running median of a sequence of numbers. | E33: Compute the running median of a sequence of numbers. That is, given a stream of numbers, print out the median of the list so far on each new element. Recall that the median of an even-numbered list is the average of the two middle numbers. For example, given the sequence [2, 1, 5, 7, 2, 0, 5], your algorithm should print out: 2 1.5 2 3.5 2 2 2 | F33: Not Started | O33: =COUNTA(G33:N33) -> 0
A34: 34 | B34: Medium | C34: Quora | D34: Given a string, find the palindrome that can be made by inserting the fewest number of characters as... | E34: Given a string, find the palindrome that can be made by inserting the fewest number of characters as possible anywhere in the word. If there is more than one palindrome of minimum length that can be made, return the lexicographically earliest one (the first one alphabetically). For example, given the string "race", you should return "ecarace", since we can add three letters to it (which is the smallest amount to make a palindrome). There are seven other palindromes that can be made from "race" by adding three letters, but "ecarace" comes first alphabetically. As another example, given the string "google", you should return "elgoogle". | F34: Not Started | O34: =COUNTA(G34:N34) -> 0
A35: 35 | B35: Hard | C35: Google | D35: Given an array of strictly the characters 'R', 'G', and 'B', segregate the values of the array so th... | E35: Given an array of strictly the characters 'R', 'G', and 'B', segregate the values of the array so that all the Rs come first, the Gs come second, and the Bs come last. You can only swap elements of the array. Do this in linear time and in-place. For example, given the array ['G', 'B', 'R', 'R', 'B', 'R', 'G'], it should become ['R', 'R', 'R', 'G', 'G', 'B', 'B']. | F35: Not Started | O35: =COUNTA(G35:N35) -> 0
A36: 36 | B36: Medium | C36: Dropbox | D36: Given the root to a binary search tree, find the second largest node in the tree. | E36: Given the root to a binary search tree, find the second largest node in the tree. | F36: Not Started | O36: =COUNTA(G36:N36) -> 0
A37: 37 | B37: Easy | C37: Google | D37: The power set of a set is the set of all its subsets. | E37: The power set of a set is the set of all its subsets. Write a function that, given a set, generates its power set. For example, given the set {1, 2, 3}, it should return {{}, {1}, {2}, {3}, {1, 2}, {1, 3}, {2, 3}, {1, 2, 3}}. You may also use a list or array to represent a set. | F37: Not Started | O37: =COUNTA(G37:N37) -> 0
A38: 38 | B38: Hard | C38: Microsoft | D38: You have an N by N board. | E38: You have an N by N board. Write a function that, given N, returns the number of possible arrangements of the board where N queens can be placed on the board without threatening each other, i.e. no two queens share the same row, column, or diagonal. | F38: Not Started | O38: =COUNTA(G38:N38) -> 0
A39: 39 | B39: Medium | C39: Dropbox | D39: Conway's Game of Life takes place on an infinite two-dimensional board of square cells. | E39: Conway's Game of Life takes place on an infinite two-dimensional board of square cells. Each cell is either dead or alive, and at each tick, the following rules apply: * Any live cell with less than two live neighbours dies. * Any live cell with two or three live neighbours remains living. * Any live cell with more than three live neighbours dies. * Any dead cell with exactly three live neighbours becomes a live cell. A cell neighbours another cell if it is horizontally, vertically, or diagonally adjacent. Implement Conway's Game of Life. It should be able to be initialized with a starting list of live cell coordinates and the number of steps it should run for. Once initialized, it should print out the board state at each step. Since it's an infinite board, print out only the relevant coordinates, i.e. from the top-leftmost live cell to bottom-rightmost live cell. You can represent a live cell with an asterisk (*) and a dead cell with a dot (. ). | F39: Not Started | O39: =COUNTA(G39:N39) -> 0
A40: 40 | B40: Hard | C40: Google | D40: Given an array of integers where every integer occurs three times except for one integer, which only... | E40: Given an array of integers where every integer occurs three times except for one integer, which only occurs once, find and return the non-duplicated integer. For example, given [6, 1, 3, 3, 3, 6, 6], return 1. Given [13, 19, 13, 13], return 19. Do this in O(N) time and O(1) space. | F40: Not Started | O40: =COUNTA(G40:N40) -> 0
A41: 41 | B41: Medium | C41: Facebook | D41: Given an unordered list of flights taken by someone, each represented as (origin, destination) pairs... | E41: Given an unordered list of flights taken by someone, each represented as (origin, destination) pairs, and a starting airport, compute the person's itinerary. If no such itinerary exists, return null. If there are multiple possible itineraries, return the lexicographically smallest one. All flights must be used in the itinerary. For example, given the list of flights [('SFO', 'HKO'), ('YYZ', 'SFO'), ('YUL', 'YYZ'), ('HKO', 'ORD')] and starting airport 'YUL', you should return the list ['YUL', 'YYZ', 'SFO', 'HKO', 'ORD']. Given the list of flights [('SFO', 'COM'), ('COM', 'YYZ')] and starting airport 'COM', you should return null. Given the list of flights [('A', 'B'), ('A', 'C'), ('B', 'C'), ('C', 'A')] and starting airport 'A', you should return the list ['A', 'B', 'C', 'A', 'C'] even though ['A', 'C', 'A', 'B', 'C'] is also a valid itinerary. However, the first one is lexicographically smaller. | F41: Not Started | O41: =COUNTA(G41:N41) -> 0
A42: 42 | B42: Hard | C42: Google | D42: Given a list of integers S and a target number k, write a function that returns a subset of S that a... | E42: Given a list of integers S and a target number k, write a function that returns a subset of S that adds up to k. If such a subset cannot be made, then return null. Integers can appear more than once in the list. You may assume all numbers in the list are positive. For example, given S = [12, 1, 61, 5, 9, 2] and k = 24, return [12, 9, 2, 1] since it sums up to 24. | F42: Not Started | O42: =COUNTA(G42:N42) -> 0
A43: 43 | B43: Easy | C43: Amazon | D43: Implement a stack that has the following methods: * push(val), which pushes an element onto the stac... | E43: Implement a stack that has the following methods: * push(val), which pushes an element onto the stack * pop(), which pops off and returns the topmost element of the stack. If there are no elements in the stack, then it should throw an error or return null. * max(), which returns the maximum value in the stack currently. If there are no elements in the stack, then it should throw an error or return null. Each method should run in constant time. | F43: Solved | J43: 46025 | O43: =COUNTA(G43:N43) -> 1
A44: 44 | B44: Medium | C44: Google | D44: We can determine how "out of order" an array A is by counting the number of inversions it has. | E44: We can determine how "out of order" an array A is by counting the number of inversions it has. Two elements A[i] and A[j] form an inversion if A[i] > A[j] but i < j. That is, a smaller element appears after a larger element. Given an array, count the number of inversions it has. Do this faster than O(N^2) time. You may assume each element in the array is distinct. For example, a sorted list has zero inversions. The array [2, 4, 1, 3, 5] has three inversions: (2, 1), (4, 1), and (4, 3). The array [5, 4, 3, 2, 1] has ten inversions: every distinct pair forms an inversion. | F44: Not Started | O44: =COUNTA(G44:N44) -> 0
A45: 45 | B45: Easy | C45: Two Sigma | D45: Using a function rand5() that returns an integer from 1 to 5 (inclusive) with uniform probability, i... | E45: Using a function rand5() that returns an integer from 1 to 5 (inclusive) with uniform probability, implement a function rand7() that returns an integer from 1 to 7 (inclusive). | F45: Not Started | O45: =COUNTA(G45:N45) -> 0
...

Sheet Summary Stats
A1: DIFFICULTY BREAKDOWN
A2: Difficulty | B2: Total | C2: Solved | D2: Not Started | E2: % Complete
A3: Easy | B3: =COUNTIF(Problems!B:B,"Easy") -> 356 | C3: =COUNTIFS(Problems!B:B,"Easy",Problems!F:F,"Solved") -> 14 | D3: =COUNTIFS(Problems!B:B,"Easy",Problems!F:F,"Not Started") -> 342 | E3: =IF(B3>0,C3/B3,0) -> 0.039325843
A4: Medium | B4: =COUNTIF(Problems!B:B,"Medium") -> 446 | C4: =COUNTIFS(Problems!B:B,"Medium",Problems!F:F,"Solved") -> 1 | D4: =COUNTIFS(Problems!B:B,"Medium",Problems!F:F,"Not Started") -> 445 | E4: =IF(B4>0,C4/B4,0) -> 0.0022421525
A5: Hard | B5: =COUNTIF(Problems!B:B,"Hard") -> 281 | C5: =COUNTIFS(Problems!B:B,"Hard",Problems!F:F,"Solved") -> 0 | D5: =COUNTIFS(Problems!B:B,"Hard",Problems!F:F,"Not Started") -> 281 | E5: =IF(B5>0,C5/B5,0) -> 0
A6: TOTAL | B6: =SUM(B3:B5) -> 1083 | C6: =SUM(C3:C5) -> 15 | D6: =SUM(D3:D5) -> 1068 | E6: =IF(B6>0,C6/B6,0) -> 0.013850416
A9: Language | B9: Total | C9: % Complete
A10: Python | B10: =COUNTA(Problems[Python]) -> 10 | C10: =B10/$B$18 -> 0.25641026
A11: C++ | B11: =COUNTA(Problems[C++]) -> 4 | C11: =B11/$B$18 -> 0.1025641
A12: Rust | B12: =COUNTA(Problems[Rust]) -> 15 | C12: =B12/$B$18 -> 0.38461538
A13: TypeScript | B13: =COUNTA(Problems[TypeScript]) -> 2 | C13: =B13/$B$18 -> 0.051282051
A14: JavaScript | B14: =COUNTA(Problems[JavaScript]) -> 4 | C14: =B14/$B$18 -> 0.1025641
A15: Bash | B15: =COUNTA(Problems[Bash]) -> 1 | C15: =B15/$B$18 -> 0.025641026
A16: C | B16: =COUNTA(Problems[C]) -> 1 | C16: =B16/$B$18 -> 0.025641026
A17: Java | B17: =COUNTA(Problems[Java]) -> 2 | C17: =B17/$B$18 -> 0.051282051
A18: Total | B18: =SUM(B10:B17) -> 39 | C18: =B18/$B$18 -> 1
